[2024-04-04 18:31:30,955] ERROR: Internal Server Error: /query/api/jobs/upload/
Traceback (most recent call last):
  File "/usr/local/lib/python3.9/site-packages/django/core/handlers/exception.py", line 55, in inner
    response = get_response(request)
  File "/usr/local/lib/python3.9/site-packages/django/core/handlers/base.py", line 197, in _get_response
    response = wrapped_callback(request, *callback_args, **callback_kwargs)
  File "/usr/local/lib/python3.9/site-packages/django/views/decorators/csrf.py", line 56, in wrapper_view
    return view_func(*args, **kwargs)
  File "/usr/local/lib/python3.9/site-packages/rest_framework/viewsets.py", line 125, in view
    return self.dispatch(request, *args, **kwargs)
  File "/usr/local/lib/python3.9/site-packages/rest_framework/views.py", line 509, in dispatch
    response = self.handle_exception(exc)
  File "/usr/local/lib/python3.9/site-packages/rest_framework/views.py", line 469, in handle_exception
    self.raise_uncaught_exception(exc)
  File "/usr/local/lib/python3.9/site-packages/rest_framework/views.py", line 480, in raise_uncaught_exception
    raise exc
  File "/usr/local/lib/python3.9/site-packages/rest_framework/views.py", line 506, in dispatch
    response = handler(request, *args, **kwargs)
  File "/usr/local/lib/python3.9/site-packages/daiquiri/query/viewsets.py", line 196, in upload
    job.ingest(file_name)
  File "/usr/local/lib/python3.9/site-packages/daiquiri/query/models.py", line 273, in ingest
    run_database_ingest_task.apply_async((self.id, file_path), queue='download')
  File "/usr/local/lib/python3.9/site-packages/celery/app/task.py", line 594, in apply_async
    return app.send_task(
  File "/usr/local/lib/python3.9/site-packages/celery/app/base.py", line 795, in send_task
    with self.producer_or_acquire(producer) as P:
  File "/usr/local/lib/python3.9/site-packages/celery/app/base.py", line 930, in producer_or_acquire
    producer, self.producer_pool.acquire, block=True,
  File "/usr/local/lib/python3.9/site-packages/celery/app/base.py", line 1352, in producer_pool
    return self.amqp.producer_pool
  File "/usr/local/lib/python3.9/site-packages/celery/app/amqp.py", line 591, in producer_pool
    self.app.connection_for_write()]
  File "/usr/local/lib/python3.9/site-packages/celery/app/base.py", line 827, in connection_for_write
    return self._connection(url or self.conf.broker_write_url, **kwargs)
  File "/usr/local/lib/python3.9/site-packages/celery/app/base.py", line 878, in _connection
    return self.amqp.Connection(
  File "/usr/local/lib/python3.9/site-packages/kombu/connection.py", line 201, in __init__
    if not get_transport_cls(transport).can_parse_url:
  File "/usr/local/lib/python3.9/site-packages/kombu/transport/__init__.py", line 90, in get_transport_cls
    _transport_cache[transport] = resolve_transport(transport)
  File "/usr/local/lib/python3.9/site-packages/kombu/transport/__init__.py", line 75, in resolve_transport
    return symbol_by_name(transport)
  File "/usr/local/lib/python3.9/site-packages/kombu/utils/imports.py", line 59, in symbol_by_name
    module = imp(module_name, package=package, **kwargs)
  File "/usr/local/lib/python3.9/importlib/__init__.py", line 127, in import_module
    return _bootstrap._gcd_import(name[level:], package, level)
  File "<frozen importlib._bootstrap>", line 1030, in _gcd_import
  File "<frozen importlib._bootstrap>", line 1007, in _find_and_load
  File "<frozen importlib._bootstrap>", line 986, in _find_and_load_unlocked
  File "<frozen importlib._bootstrap>", line 680, in _load_unlocked
  File "<frozen importlib._bootstrap_external>", line 850, in exec_module
  File "<frozen importlib._bootstrap>", line 228, in _call_with_frames_removed
  File "/usr/local/lib/python3.9/site-packages/kombu/transport/redis.py", line 267, in <module>
    class PrefixedStrictRedis(GlobalKeyPrefixMixin, redis.Redis):
AttributeError: 'NoneType' object has no attribute 'Redis'
